<mujoco model="panda">
    <actuator>
        
        <motor ctrllimited="true" ctrlrange="-80.0 80.0" joint="0_joint1" name="0_torq_j1" />
        <motor ctrllimited="true" ctrlrange="-80.0 80.0" joint="0_joint2" name="0_torq_j2" />
        <motor ctrllimited="true" ctrlrange="-80.0 80.0" joint="0_joint3" name="0_torq_j3" />
        <motor ctrllimited="true" ctrlrange="-80.0 80.0" joint="0_joint4" name="0_torq_j4" />
        <motor ctrllimited="true" ctrlrange="-80.0 80.0" joint="0_joint5" name="0_torq_j5" />
        <motor ctrllimited="true" ctrlrange="-12.0 12.0" joint="0_joint6" name="0_torq_j6" />
        <motor ctrllimited="true" ctrlrange="-12.0 12.0" joint="0_joint7" name="0_torq_j7" />
    </actuator>
    <asset>
        <mesh file="/home/lthpc/Desktop/meta-role/robosuite/robosuite/models/assets/robots/panda/meshes/link0.stl" name="0_link0" />
        <mesh file="/home/lthpc/Desktop/meta-role/robosuite/robosuite/models/assets/robots/panda/meshes/link1.stl" name="0_link1" />
        <mesh file="/home/lthpc/Desktop/meta-role/robosuite/robosuite/models/assets/robots/panda/meshes/link2.stl" name="0_link2" />
        <mesh file="/home/lthpc/Desktop/meta-role/robosuite/robosuite/models/assets/robots/panda/meshes/link3.stl" name="0_link3" />
        <mesh file="/home/lthpc/Desktop/meta-role/robosuite/robosuite/models/assets/robots/panda/meshes/link4.stl" name="0_link4" />
        <mesh file="/home/lthpc/Desktop/meta-role/robosuite/robosuite/models/assets/robots/panda/meshes/link5.stl" name="0_link5" />
        <mesh file="/home/lthpc/Desktop/meta-role/robosuite/robosuite/models/assets/robots/panda/meshes/link6.stl" name="0_link6" />
        <mesh file="/home/lthpc/Desktop/meta-role/robosuite/robosuite/models/assets/robots/panda/meshes/link7.stl" name="0_link7" />
        <mesh file="/home/lthpc/Desktop/meta-role/robosuite/robosuite/models/assets/robots/panda/meshes/link0_vis.stl" name="0_link0_vis" />
        <mesh file="/home/lthpc/Desktop/meta-role/robosuite/robosuite/models/assets/robots/panda/meshes/link1_vis.stl" name="0_link1_vis" />
        <mesh file="/home/lthpc/Desktop/meta-role/robosuite/robosuite/models/assets/robots/panda/meshes/link2_vis.stl" name="0_link2_vis" />
        <mesh file="/home/lthpc/Desktop/meta-role/robosuite/robosuite/models/assets/robots/panda/meshes/link3_vis.stl" name="0_link3_vis" />
        <mesh file="/home/lthpc/Desktop/meta-role/robosuite/robosuite/models/assets/robots/panda/meshes/link4_vis.stl" name="0_link4_vis" />
        <mesh file="/home/lthpc/Desktop/meta-role/robosuite/robosuite/models/assets/robots/panda/meshes/link5_vis.stl" name="0_link5_vis" />
        <mesh file="/home/lthpc/Desktop/meta-role/robosuite/robosuite/models/assets/robots/panda/meshes/link6_vis.stl" name="0_link6_vis" />
        <mesh file="/home/lthpc/Desktop/meta-role/robosuite/robosuite/models/assets/robots/panda/meshes/link7_vis.stl" name="0_link7_vis" />
    </asset>
    <worldbody>
        <body name="0_base" pos="0 0 0">
            
            <camera mode="fixed" name="0_robotview" pos="1.0 0 0.4" quat="0.653 0.271 0.271 0.653" />
            <inertial diaginertia="0 0 0" mass="0.0" pos="0 0 0" />
            
            <body name="0_link0" pos="0 0 0">
                <inertial diaginertia="0.4 0.4 0.4" mass="8.0" pos="0 0 0.05" />
                <geom conaffinity="0" contype="0" group="1" mesh="0_link0_vis" name="0_link0_visual" rgba="1 1 1 1" type="mesh" />
                <geom group="0" mesh="0_link0" name="0_link0_collision" rgba="" type="mesh" />
                <body name="0_link1" pos="0 0 0.333">
                    <inertial diaginertia="0.3 0.3 0.3" mass="6.0" pos="0 0 -0.07" />
                    <joint axis="0 0 1" damping="0.1" limited="true" name="0_joint1" pos="0 0 0" range="-2.8973 2.8973" />
                    <geom conaffinity="0" contype="0" group="1" mesh="0_link1_vis" name="0_link1_visual" rgba="1 1 1 1" type="mesh" />
                    <geom group="0" mesh="0_link1" name="0_link1_collision" rgba="" type="mesh" />
                    <body name="0_link2" pos="0 0 0" quat="0.707107 -0.707107 0 0">
                        <inertial diaginertia="0.3 0.3 0.3" mass="6.0" pos="0 -0.1 0" />
                        <joint axis="0 0 1" damping="0.1" limited="true" name="0_joint2" pos="0 0 0" range="-1.7628 1.7628" />
                        <geom conaffinity="0" contype="0" group="1" mesh="0_link2_vis" name="0_link2_visual" rgba="1 1 1 1" type="mesh" />
                        <geom group="0" mesh="0_link2" name="0_link2_collision" rgba="" type="mesh" />
                        <body name="0_link3" pos="0 -0.316 0" quat="0.707107 0.707107 0 0">
                            <inertial diaginertia="0.2 0.2 0.2" mass="4.0" pos="0.04 0 -0.05" />
                            <joint axis="0 0 1" damping="0.1" limited="true" name="0_joint3" pos="0 0 0" range="-2.8973 2.8973" />
                            <geom conaffinity="0" contype="0" group="1" mesh="0_link3_vis" name="0_link3_visual" rgba="1 1 1 1" type="mesh" />
                            <geom group="0" mesh="0_link3" name="0_link3_collision" rgba="" type="mesh" />
                            <body name="0_link4" pos="0.0825 0 0" quat="0.707107 0.707107 0 0">
                                <inertial diaginertia="0.2 0.2 0.2" mass="4.0" pos="-0.04 0.05 0" />
                                <joint axis="0 0 1" damping="0.1" limited="true" name="0_joint4" pos="0 0 0" range="-3.0718 -0.0698" />
                                <geom conaffinity="0" contype="0" group="1" mesh="0_link4_vis" name="0_link4_visual" rgba="1 1 1 1" type="mesh" />
                                <geom group="0" mesh="0_link4" name="0_link4_collision" rgba="" type="mesh" />
                                <body name="0_link5" pos="-0.0825 0.384 0" quat="0.707107 -0.707107 0 0">
                                    <inertial diaginertia="0.2 0.2 0.2" mass="4.0" pos="0 0 -0.15" />
                                    <joint axis="0 0 1" damping="0.1" limited="true" name="0_joint5" pos="0 0 0" range="-2.8973 2.8973" />
                                    <geom conaffinity="0" contype="0" group="1" mesh="0_link5_vis" name="0_link5_visual" rgba="1 1 1 1" type="mesh" />
                                    <geom group="0" mesh="0_link5" name="0_link5_collision" rgba="" type="mesh" />
                                    <body name="0_link6" pos="0 0 0" quat="0.707107 0.707107 0 0">
                                        <inertial diaginertia="0.1 0.1 0.1" mass="3.0" pos="0.06 0 0" />
                                        <joint axis="0 0 1" damping="0.01" limited="true" name="0_joint6" pos="0 0 0" range="-0.0175 3.7525" />
                                        <geom conaffinity="0" contype="0" group="1" mesh="0_link6_vis" name="0_link6_visual" rgba="1 1 1 1" type="mesh" />
                                        <geom group="0" mesh="0_link6" name="0_link6_collision" rgba="" type="mesh" />
                                        <body name="0_link7" pos="0.088 0 0" quat="0.707107 0.707107 0 0">
                                            <inertial diaginertia="0.05 0.05 0.05" mass="1.0" pos="0 0 0.08" />
                                            <joint axis="0 0 1" damping="0.01" limited="true" name="0_joint7" pos="0 0 0" range="-2.8973 2.8973" />
                                            <geom conaffinity="0" contype="0" group="1" mesh="0_link7_vis" name="0_link7_visual" rgba="1. 1. 1. 1." type="mesh" />
                                            <geom group="0" mesh="0_link7" name="0_link7_collision" rgba="" type="mesh" />
                                            
                                            <body name="0_right_hand" pos="0 0 0.1065" quat="0.924 0 0 -0.383">
                                                <inertial diaginertia="0.05 0.05 0.05" mass="1.0" pos="0 0 0" />
                                                
                                                
                                                
                                                <site group="1" name="0_ee" pos="0 0 0" rgba="0 0 1 1" size="0.01 0.01 0.01" type="sphere" />
                                                <site group="1" name="0_ee_x" pos="0 0 0" quat="0.707105 0.707108 0 0 " rgba="1 0 0 0" size="0.005 .1" type="cylinder" />
                                                <site group="1" name="0_ee_z" pos="0 0 0" quat="0.707105 0 0 0.707108" rgba="0 0 1 0" size="0.005 .1" type="cylinder" />
                                                <site group="1" name="0_ee_y" pos="0 0 0" quat="0.707105 0 0.707108 0 " rgba="0 1 0 0" size="0.005 .1" type="cylinder" />
                                                
                                                <camera fovy="75" mode="fixed" name="0_eye_in_hand" pos="0.05 0 0" quat="0 0.707108 0.707108 0" />
                                                
                                            </body>
                                        </body>
                                    </body>
                                </body>
                            </body>
                        </body>
                    </body>
                </body>
            </body>
        </body>
    </worldbody>
<sensor /><tendon /><equality /><contact /><default /></mujoco>